Workbook

Sheet Overview
A1: RedditSummit – 3-Sprint Plan
A2: Team: Jalal, Khan, Wesley, Ayman | Plan window: 9/22/2026 – 11/19/2026
A4: Sprint | B4: Start | C4: End | D4: Days | E4: Goal | F4: Check-in dates | G4: Points | H4: Est. Hrs
A5: Sprint 1 | B5: 46287 | C5: 46306 | D5: =C5-B5+1 -> 20 | E5: Foundation: accounts, login, create post, post feed | F5: 9/28, 10/2, 10/6, 10/10 | G5: ='Sprint 1'!D31 -> 20 | H5: ='Sprint 1'!E31 -> 92
A6: Sprint 2 | B6: 46307 | C6: 46326 | D6: =C6-B6+1 -> 20 | E6: Discussion: replies, category filter, anonymous posting, my activity | F6: 10/16, 10/20, 10/24, 10/29 | G6: ='Sprint 2'!D32 -> 26 | H6: ='Sprint 2'!E32 -> 86
A7: Sprint 3 | B7: 46327 | C7: 46345 | D7: =C7-B7+1 -> 19 | E7: AI summary twist, likes, testing, final demo | F7: 11/5, 11/9, 11/13, 11/17 | G7: ='Sprint 3'!D36 -> 26 | H7: ='Sprint 3'!E36 -> 105
A8: Total | G8: =SUM(G5:G7) -> 72 | H8: =SUM(H5:H7) -> 283
A10: Workload by member
A11: Member | B11: S1 Points | C11: S2 Points | D11: S3 Points | E11: Total Points | F11: S1 Hrs | G11: S2 Hrs | H11: S3 Hrs | I11: Total Hrs
A12: Jalal | B12: =SUMIFS('Sprint 1'!$D$2:$D$30,'Sprint 1'!$A$2:$A$30,"Jalal") -> 5 | C12: =SUMIFS('Sprint 2'!$D$2:$D$31,'Sprint 2'!$A$2:$A$31,"Jalal") -> 8 | D12: =SUMIFS('Sprint 3'!$D$2:$D$35,'Sprint 3'!$A$2:$A$35,"Jalal") -> 8 | E12: =SUM(B12:D12) -> 21 | F12: =SUMIFS('Sprint 1'!$E$2:$E$30,'Sprint 1'!$A$2:$A$30,"Jalal") -> 24 | G12: =SUMIFS('Sprint 2'!$E$2:$E$31,'Sprint 2'!$A$2:$A$31,"Jalal") -> 24 | H12: =SUMIFS('Sprint 3'!$E$2:$E$35,'Sprint 3'!$A$2:$A$35,"Jalal") -> 23 | I12: =SUM(F12:H12) -> 71
A13: Khan | B13: =SUMIFS('Sprint 1'!$D$2:$D$30,'Sprint 1'!$A$2:$A$30,"Khan") -> 5 | C13: =SUMIFS('Sprint 2'!$D$2:$D$31,'Sprint 2'!$A$2:$A$31,"Khan") -> 8 | D13: =SUMIFS('Sprint 3'!$D$2:$D$35,'Sprint 3'!$A$2:$A$35,"Khan") -> 5 | E13: =SUM(B13:D13) -> 18 | F13: =SUMIFS('Sprint 1'!$E$2:$E$30,'Sprint 1'!$A$2:$A$30,"Khan") -> 23 | G13: =SUMIFS('Sprint 2'!$E$2:$E$31,'Sprint 2'!$A$2:$A$31,"Khan") -> 24 | H13: =SUMIFS('Sprint 3'!$E$2:$E$35,'Sprint 3'!$A$2:$A$35,"Khan") -> 20 | I13: =SUM(F13:H13) -> 67
A14: Wesley | B14: =SUMIFS('Sprint 1'!$D$2:$D$30,'Sprint 1'!$A$2:$A$30,"Wesley") -> 5 | C14: =SUMIFS('Sprint 2'!$D$2:$D$31,'Sprint 2'!$A$2:$A$31,"Wesley") -> 5 | D14: =SUMIFS('Sprint 3'!$D$2:$D$35,'Sprint 3'!$A$2:$A$35,"Wesley") -> 5 | E14: =SUM(B14:D14) -> 15 | F14: =SUMIFS('Sprint 1'!$E$2:$E$30,'Sprint 1'!$A$2:$A$30,"Wesley") -> 22 | G14: =SUMIFS('Sprint 2'!$E$2:$E$31,'Sprint 2'!$A$2:$A$31,"Wesley") -> 20 | H14: =SUMIFS('Sprint 3'!$E$2:$E$35,'Sprint 3'!$A$2:$A$35,"Wesley") -> 20 | I14: =SUM(F14:H14) -> 62
A15: Ayman | B15: =SUMIFS('Sprint 1'!$D$2:$D$30,'Sprint 1'!$A$2:$A$30,"Ayman") -> 5 | C15: =SUMIFS('Sprint 2'!$D$2:$D$31,'Sprint 2'!$A$2:$A$31,"Ayman") -> 5 | D15: =SUMIFS('Sprint 3'!$D$2:$D$35,'Sprint 3'!$A$2:$A$35,"Ayman") -> 5 | E15: =SUM(B15:D15) -> 15 | F15: =SUMIFS('Sprint 1'!$E$2:$E$30,'Sprint 1'!$A$2:$A$30,"Ayman") -> 23 | G15: =SUMIFS('Sprint 2'!$E$2:$E$31,'Sprint 2'!$A$2:$A$31,"Ayman") -> 18 | H15: =SUMIFS('Sprint 3'!$E$2:$E$35,'Sprint 3'!$A$2:$A$35,"Ayman") -> 16 | I15: =SUM(F15:H15) -> 57
A16: All (team story) | B16: =SUMIFS('Sprint 1'!$D$2:$D$30,'Sprint 1'!$A$2:$A$30,"All") -> 0 | C16: =SUMIFS('Sprint 2'!$D$2:$D$31,'Sprint 2'!$A$2:$A$31,"All") -> 0 | D16: =SUMIFS('Sprint 3'!$D$2:$D$35,'Sprint 3'!$A$2:$A$35,"All") -> 3 | E16: =SUM(B16:D16) -> 3 | F16: =SUMIFS('Sprint 1'!$E$2:$E$30,'Sprint 1'!$A$2:$A$30,"All") -> 0 | G16: =SUMIFS('Sprint 2'!$E$2:$E$31,'Sprint 2'!$A$2:$A$31,"All") -> 0 | H16: =SUMIFS('Sprint 3'!$E$2:$E$35,'Sprint 3'!$A$2:$A$35,"All") -> 26 | I16: =SUM(F16:H16) -> 26
A17: Total | B17: =SUM(B12:B16) -> 20 | C17: =SUM(C12:C16) -> 26 | D17: =SUM(D12:D16) -> 26 | E17: =SUM(E12:E16) -> 72 | F17: =SUM(F12:F16) -> 92 | G17: =SUM(G12:G16) -> 86 | H17: =SUM(H12:H16) -> 105 | I17: =SUM(I12:I16) -> 283
A19: Assumptions & notes
A20: • Sprint lengths: S1 20 days, S2 20 days, S3 19 days; each sprint ends with a review & retrospective (S3 ends with the final demo on 11/19).
A21: • Points use a Fibonacci scale (3/5/8); hours are initial team estimates — adjust them in the sprint tabs during planning.
A22: • AI summary reply threshold is assumed to be 5 replies (the backlog doesn't set a number) — confirm with the team.
A23: • 'Like a post' and 'Like a comment' come from the workflow diagram but are not in the product backlog; they are planned last (Sprint 3) so they can be dropped if time runs short.
A24: • Sprint order builds dependencies first: accounts → posts → replies/categories → anonymous posting → AI summary.
A25: • How to use: fill Hrs Left on task rows in each Sprint tab at every check-in; story rows, totals, and this overview update automatically.

Sheet Schedule
A1: RedditSummit – Sprint Schedule (9/22/2026 – 11/19/2026)
A2: Bars are colored by owner. Gray columns are weekends. ◆ = sprint review / milestone. Change Start/End dates and the bars move.
G3: September 2026 | P3: October 2026 | AU3: November 2026
G4: T | H4: W | I4: T | J4: F | K4: S | L4: S | M4: M | N4: T | O4: W | P4: T | Q4: F | R4: S | S4: S | T4: M | U4: T | V4: W | W4: T | X4: F | Y4: S | Z4: S | AA4: M | AB4: T | AC4: W | AD4: T | AE4: F | AF4: S | AG4: S | AH4: M | AI4: T | AJ4: W | AK4: T | AL4: F | AM4: S | AN4: S | AO4: M | AP4: T | AQ4: W | AR4: T | AS4: F | AT4: S | AU4: S | AV4: M | AW4: T | AX4: W | AY4: T | AZ4: F | BA4: S | BB4: S | BC4: M | BD4: T | BE4: W | BF4: T | BG4: F | BH4: S | BI4: S | BJ4: M | BK4: T | BL4: W | BM4: T
A5: Sprint | B5: Owner | C5: Work item | D5: Start | E5: End | F5: Days | G5: 46287 | H5: 46288 | I5: 46289 | J5: 46290 | K5: 46291 | L5: 46292 | M5: 46293 | N5: 46294 | O5: 46295 | P5: 46296 | Q5: 46297 | R5: 46298 | S5: 46299 | T5: 46300 | U5: 46301 | V5: 46302 | W5: 46303 | X5: 46304 | Y5: 46305 | Z5: 46306 | AA5: 46307 | AB5: 46308 | AC5: 46309 | AD5: 46310 | AE5: 46311 | AF5: 46312 | AG5: 46313 | AH5: 46314 | AI5: 46315 | AJ5: 46316 | AK5: 46317 | AL5: 46318 | AM5: 46319 | AN5: 46320 | AO5: 46321 | AP5: 46322 | AQ5: 46323 | AR5: 46324 | AS5: 46325 | AT5: 46326 | AU5: 46327 | AV5: 46328 | AW5: 46329 | AX5: 46330 | AY5: 46331 | AZ5: 46332 | BA5: 46333 | BB5: 46334 | BC5: 46335 | BD5: 46336 | BE5: 46337 | BF5: 46338 | BG5: 46339 | BH5: 46340 | BI5: 46341 | BJ5: 46342 | BK5: 46343 | BL5: 46344 | BM5: 46345
A6: Sprint 1 | C6: Foundation: accounts, login, create post, post feed | D6: 46287 | E6: 46306 | F6: =E6-D6+1 -> 20
A7: S1 | B7: Jalal | C7: As a user, I can register for an account with a unique username and email. | D7: =MIN(D8:D13) -> 46287 | E7: =MAX(E8:E13) -> 46305 | F7: =E7-D7+1 -> 19
A8: S1 | B8: Jalal | C8: Set up backend project, database, and users table | D8: 46287 | E8: 46291 | F8: =E8-D8+1 -> 5
A9: S1 | B9: Jalal | C9: Build registration API with password hashing and duplicate checks | D9: 46292 | E9: 46296 | F9: =E9-D9+1 -> 5
A10: S1 | B10: Jalal | C10: Create registration screen UI | D10: 46297 | E10: 46300 | F10: =E10-D10+1 -> 4
A11: S1 | B11: Jalal | C11: Add input validation and error messages | D11: 46301 | E11: 46302 | F11: =E11-D11+1 -> 2
A12: S1 | B12: Jalal | C12: Review & check-in | D12: 46303 | E12: 46305 | F12: =E12-D12+1 -> 3
A13: S1 | B13: Jalal | C13: Document | D13: 46301 | E13: 46305 | F13: =E13-D13+1 -> 5
A14: S1 | B14: Wesley | C14: As a user, I can log in and stay logged in while I use the app. | D14: =MIN(D15:D20) -> 46287 | E14: =MAX(E15:E20) -> 46305 | F14: =E14-D14+1 -> 19
A15: S1 | B15: Wesley | C15: Build login API with token-based session | D15: 46287 | E15: 46291 | F15: =E15-D15+1 -> 5
A16: S1 | B16: Wesley | C16: Create login screen UI | D16: 46292 | E16: 46295 | F16: =E16-D16+1 -> 4
A17: S1 | B17: Wesley | C17: Persist session across app restarts and add logout | D17: 46296 | E17: 46298 | F17: =E17-D17+1 -> 3
A18: S1 | B18: Wesley | C18: Require login before creating posts or replies | D18: 46299 | E18: 46302 | F18: =E18-D18+1 -> 4
A19: S1 | B19: Wesley | C19: Review & check-in | D19: 46303 | E19: 46305 | F19: =E19-D19+1 -> 3
A20: S1 | B20: Wesley | C20: Document | D20: 46301 | E20: 46305 | F20: =E20-D20+1 -> 5
A21: S1 | B21: Khan | C21: As a user, I can create a post with a title, description, and category. | D21: =MIN(D22:D27) -> 46287 | E21: =MAX(E22:E27) -> 46305 | F21: =E21-D21+1 -> 19
A22: S1 | B22: Khan | C22: Create posts and categories tables; seed predefined categories | D22: 46287 | E22: 46290 | F22: =E22-D22+1 -> 4
A23: S1 | B23: Khan | C23: Build create-post API (logged-in users only) | D23: 46291 | E23: 46294 | F23: =E23-D23+1 -> 4
A24: S1 | B24: Khan | C24: Create post composer screen with category picker | D24: 46295 | E24: 46299 | F24: =E24-D24+1 -> 5
A25: S1 | B25: Khan | C25: Validate title, description, and required category | D25: 46300 | E25: 46302 | F25: =E25-D25+1 -> 3
A26: S1 | B26: Khan | C26: Review & check-in | D26: 46303 | E26: 46305 | F26: =E26-D26+1 -> 3
A27: S1 | B27: Khan | C27: Document | D27: 46301 | E27: 46305 | F27: =E27-D27+1 -> 5
A28: S1 | B28: Ayman | C28: As a user, I can browse posts created by other users in a feed. | D28: =MIN(D29:D34) -> 46287 | E28: =MAX(E29:E34) -> 46305 | F28: =E28-D28+1 -> 19
A29: S1 | B29: Ayman | C29: Set up mobile app skeleton and screen navigation | D29: 46287 | E29: 46290 | F29: =E29-D29+1 -> 4
A30: S1 | B30: Ayman | C30: Build feed API (newest first, paginated) | D30: 46291 | E30: 46294 | F30: =E30-D30+1 -> 4
A31: S1 | B31: Ayman | C31: Create feed screen with post cards (title, category, author, reply count) | D31: 46295 | E31: 46299 | F31: =E31-D31+1 -> 5
A32: S1 | B32: Ayman | C32: Add pull-to-refresh plus loading and empty states | D32: 46300 | E32: 46302 | F32: =E32-D32+1 -> 3
A33: S1 | B33: Ayman | C33: Review & check-in | D33: 46303 | E33: 46305 | F33: =E33-D33+1 -> 3
A34: S1 | B34: Ayman | C34: Document | D34: 46301 | E34: 46305 | F34: =E34-D34+1 -> 5
A35: S1 | B35: All | C35: ◆ Sprint 1 review & retrospective | D35: 46306 | E35: 46306 | F35: =E35-D35+1 -> 1
A36: Sprint 2 | C36: Discussion: replies, category filter, anonymous posting, my activity | D36: 46307 | E36: 46326 | F36: =E36-D36+1 -> 20
A37: S2 | B37: Khan | C37: As a user, I can open a post and reply to the discussion. | D37: =MIN(D38:D43) -> 46307 | E37: =MAX(E38:E43) -> 46325 | F37: =E37-D37+1 -> 19
A38: S2 | B38: Khan | C38: Create replies table linked to post and author | D38: 46307 | E38: 46308 | F38: =E38-D38+1 -> 2
A39: S2 | B39: Khan | C39: Build reply API; update reply count in the same transaction | D39: 46309 | E39: 46313 | F39: =E39-D39+1 -> 5
A40: S2 | B40: Khan | C40: Create post detail screen showing the full discussion | D40: 46314 | E40: 46318 | F40: =E40-D40+1 -> 5
...

Sheet Sprint 1
A1: Owner | B1: User Story | C1: Task | D1: Points | E1: Est. (Hrs) | F1: Hrs Left (9/28) | G1: Hrs Left (10/2) | H1: Hrs Left (10/6) | I1: Hrs Left (10/10)
A2: Jalal | B2: As a user, I can register for an account with a unique username and email. | D2: 5 | E2: =SUM(E3:E8) -> 24 | F2: =IF(COUNT(F3:F8)=0,"",SUM(F3:F8)) | G2: =IF(COUNT(G3:G8)=0,"",SUM(G3:G8)) | H2: =IF(COUNT(H3:H8)=0,"",SUM(H3:H8)) | I2: =IF(COUNT(I3:I8)=0,"",SUM(I3:I8))
C3: Set up backend project, database, and users table | E3: 6
C4: Build registration API with password hashing and duplicate checks | E4: 6
C5: Create registration screen UI | E5: 5
C6: Add input validation and error messages | E6: 3
C7: Review & check-in | E7: 2
C8: Document | E8: 2
A9: Wesley | B9: As a user, I can log in and stay logged in while I use the app. | D9: 5 | E9: =SUM(E10:E15) -> 22 | F9: =IF(COUNT(F10:F15)=0,"",SUM(F10:F15)) | G9: =IF(COUNT(G10:G15)=0,"",SUM(G10:G15)) | H9: =IF(COUNT(H10:H15)=0,"",SUM(H10:H15)) | I9: =IF(COUNT(I10:I15)=0,"",SUM(I10:I15))
C10: Build login API with token-based session | E10: 6
C11: Create login screen UI | E11: 4
C12: Persist session across app restarts and add logout | E12: 4
C13: Require login before creating posts or replies | E13: 4
C14: Review & check-in | E14: 2
C15: Document | E15: 2
A16: Khan | B16: As a user, I can create a post with a title, description, and category. | D16: 5 | E16: =SUM(E17:E22) -> 23 | F16: =IF(COUNT(F17:F22)=0,"",SUM(F17:F22)) | G16: =IF(COUNT(G17:G22)=0,"",SUM(G17:G22)) | H16: =IF(COUNT(H17:H22)=0,"",SUM(H17:H22)) | I16: =IF(COUNT(I17:I22)=0,"",SUM(I17:I22))
C17: Create posts and categories tables; seed predefined categories | E17: 5
C18: Build create-post API (logged-in users only) | E18: 5
C19: Create post composer screen with category picker | E19: 6
C20: Validate title, description, and required category | E20: 3
C21: Review & check-in | E21: 2
C22: Document | E22: 2
A23: Ayman | B23: As a user, I can browse posts created by other users in a feed. | D23: 5 | E23: =SUM(E24:E29) -> 23 | F23: =IF(COUNT(F24:F29)=0,"",SUM(F24:F29)) | G23: =IF(COUNT(G24:G29)=0,"",SUM(G24:G29)) | H23: =IF(COUNT(H24:H29)=0,"",SUM(H24:H29)) | I23: =IF(COUNT(I24:I29)=0,"",SUM(I24:I29))
C24: Set up mobile app skeleton and screen navigation | E24: 5
C25: Build feed API (newest first, paginated) | E25: 5
C26: Create feed screen with post cards (title, category, author, reply count) | E26: 6
C27: Add pull-to-refresh plus loading and empty states | E27: 3
C28: Review & check-in | E28: 2
C29: Document | E29: 2
A31: Total | D31: =D2+D9+D16+D23 -> 20 | E31: =E2+E9+E16+E23 -> 92 | F31: =IF(COUNT(F2,F9,F16,F23)=0,"",N(F2)+N(F9)+N(F16)+N(F23)) | G31: =IF(COUNT(G2,G9,G16,G23)=0,"",N(G2)+N(G9)+N(G16)+N(G23)) | H31: =IF(COUNT(H2,H9,H16,H23)=0,"",N(H2)+N(H9)+N(H16)+N(H23)) | I31: =IF(COUNT(I2,I9,I16,I23)=0,"",N(I2)+N(I9)+N(I16)+N(I23))
A33: Sprint 1: 9/22/2026 – 10/11/2026. Goal: Foundation: accounts, login, create post, post feed.
A34: Fill in Hrs Left on task rows at each check-in; story and total rows add up automatically.

Sheet Sprint 2
A1: Owner | B1: User Story | C1: Task | D1: Points | E1: Est. (Hrs) | F1: Hrs Left (10/16) | G1: Hrs Left (10/20) | H1: Hrs Left (10/24) | I1: Hrs Left (10/29)
A2: Khan | B2: As a user, I can open a post and reply to the discussion. | D2: 8 | E2: =SUM(E3:E8) -> 24 | F2: =IF(COUNT(F3:F8)=0,"",SUM(F3:F8)) | G2: =IF(COUNT(G3:G8)=0,"",SUM(G3:G8)) | H2: =IF(COUNT(H3:H8)=0,"",SUM(H3:H8)) | I2: =IF(COUNT(I3:I8)=0,"",SUM(I3:I8))
C3: Create replies table linked to post and author | E3: 3
C4: Build reply API; update reply count in the same transaction | E4: 6
C5: Create post detail screen showing the full discussion | E5: 6
C6: Add reply composer so new replies appear in the thread | E6: 5
C7: Review & check-in | E7: 2
C8: Document | E8: 2
A9: Ayman | B9: As a user, I can browse and filter posts by category. | D9: 5 | E9: =SUM(E10:E15) -> 18 | F9: =IF(COUNT(F10:F15)=0,"",SUM(F10:F15)) | G9: =IF(COUNT(G10:G15)=0,"",SUM(G10:G15)) | H9: =IF(COUNT(H10:H15)=0,"",SUM(H10:H15)) | I9: =IF(COUNT(I10:I15)=0,"",SUM(I10:I15))
C10: Add category filter to the feed API | E10: 4
C11: Build category filter chips on the feed screen | E11: 5
C12: Show category label on post cards and post detail | E12: 3
C13: Handle categories with no posts (empty state) | E13: 2
C14: Review & check-in | E14: 2
C15: Document | E15: 2
A16: Jalal | B16: As a user, I can publish a post anonymously. | D16: 8 | E16: =SUM(E17:E23) -> 24 | F16: =IF(COUNT(F17:F23)=0,"",SUM(F17:F23)) | G16: =IF(COUNT(G17:G23)=0,"",SUM(G17:G23)) | H16: =IF(COUNT(H17:H23)=0,"",SUM(H17:H23)) | I16: =IF(COUNT(I17:I23)=0,"",SUM(I17:I23))
C17: Add is_anonymous field while keeping the internal author link | E17: 3
C18: Strip author identity from API responses for anonymous posts | E18: 5
C19: Add Anonymous Post toggle to the post composer | E19: 3
C20: Show 'Anonymous' on feed/detail; label author's own replies 'Anonymous (OP)' | E20: 5
C21: Write privacy tests: no identity leaks through API or UI | E21: 4
C22: Review & check-in | E22: 2
C23: Document | E23: 2
A24: Wesley | B24: As a user, I can view my own posts and replies. | D24: 5 | E24: =SUM(E25:E30) -> 20 | F24: =IF(COUNT(F25:F30)=0,"",SUM(F25:F30)) | G24: =IF(COUNT(G25:G30)=0,"",SUM(G25:G30)) | H24: =IF(COUNT(H25:H30)=0,"",SUM(H25:H30)) | I24: =IF(COUNT(I25:I30)=0,"",SUM(I25:I30))
C25: Build my-activity API (visible only to the owner) | E25: 5
C26: Create My Posts & Replies screen | E26: 5
C27: Enforce ownership checks so users can't modify others' content | E27: 4
C28: Include my anonymous posts, marked as anonymous | E28: 2
C29: Review & check-in | E29: 2
C30: Document | E30: 2
A32: Total | D32: =D2+D9+D16+D24 -> 26 | E32: =E2+E9+E16+E24 -> 86 | F32: =IF(COUNT(F2,F9,F16,F24)=0,"",N(F2)+N(F9)+N(F16)+N(F24)) | G32: =IF(COUNT(G2,G9,G16,G24)=0,"",N(G2)+N(G9)+N(G16)+N(G24)) | H32: =IF(COUNT(H2,H9,H16,H24)=0,"",N(H2)+N(H9)+N(H16)+N(H24)) | I32: =IF(COUNT(I2,I9,I16,I24)=0,"",N(I2)+N(I9)+N(I16)+N(I24))
A34: Sprint 2: 10/12/2026 – 10/31/2026. Goal: Discussion: replies, category filter, anonymous posting, my activity.
A35: Fill in Hrs Left on task rows at each check-in; story and total rows add up automatically.

Sheet Sprint 3
A1: Owner | B1: User Story | C1: Task | D1: Points | E1: Est. (Hrs) | F1: Hrs Left (11/5) | G1: Hrs Left (11/9) | H1: Hrs Left (11/13) | I1: Hrs Left (11/17)
A2: Jalal | B2: As a user, I can view an AI summary once a post reaches the reply threshold. | D2: 8 | E2: =SUM(E3:E8) -> 23 | F2: =IF(COUNT(F3:F8)=0,"",SUM(F3:F8)) | G2: =IF(COUNT(G3:G8)=0,"",SUM(G3:G8)) | H2: =IF(COUNT(H3:H8)=0,"",SUM(H3:H8)) | I2: =IF(COUNT(I3:I8)=0,"",SUM(I3:I8))
C3: Create summaries table (text, generated time, reply count at generation) | E3: 3
C4: Build server-side LLM service; API key kept in server environment | E4: 6
C5: Design summary prompt: send reply text only, no account info | E5: 4
C6: Build summarize endpoint with threshold check and error handling | E6: 6
C7: Review & check-in | E7: 2
C8: Document | E8: 2
A9: Khan | B9: As a user, I can refresh the AI summary after new replies are added. | D9: 5 | E9: =SUM(E10:E15) -> 20 | F9: =IF(COUNT(F10:F15)=0,"",SUM(F10:F15)) | G9: =IF(COUNT(G10:G15)=0,"",SUM(G10:G15)) | H9: =IF(COUNT(H10:H15)=0,"",SUM(H10:H15)) | I9: =IF(COUNT(I10:I15)=0,"",SUM(I10:I15))
C10: Detect replies added since the last summary | E10: 4
C11: Build refresh endpoint that uses the updated set of replies | E11: 5
C12: Prevent duplicate refreshes (in-progress lock and rate limit) | E12: 4
C13: Show Refresh button only when new replies exist | E13: 3
C14: Review & check-in | E14: 2
C15: Document | E15: 2
A16: Ayman | B16: As a user, I can see the summary clearly labeled as AI-generated. | D16: 5 | E16: =SUM(E17:E22) -> 16 | F16: =IF(COUNT(F17:F22)=0,"",SUM(F17:F22)) | G16: =IF(COUNT(G17:G22)=0,"",SUM(G17:G22)) | H16: =IF(COUNT(H17:H22)=0,"",SUM(H17:H22)) | I16: =IF(COUNT(I17:I22)=0,"",SUM(I17:I22))
C17: Build summary panel on the post detail screen | E17: 5
C18: Add 'AI-generated' label and generation timestamp | E18: 2
C19: Hide the summary option below the reply threshold | E19: 2
C20: Add loading and error states for summary requests | E20: 3
C21: Review & check-in | E21: 2
C22: Document | E22: 2
A23: Wesley | B23: As a user, I can like posts and comments. | D23: 5 | E23: =SUM(E24:E29) -> 20 | F23: =IF(COUNT(F24:F29)=0,"",SUM(F24:F29)) | G23: =IF(COUNT(G24:G29)=0,"",SUM(G24:G29)) | H23: =IF(COUNT(H24:H29)=0,"",SUM(H24:H29)) | I23: =IF(COUNT(I24:I29)=0,"",SUM(I24:I29))
C24: Create likes table (one like per user per item) | E24: 3
C25: Build like/unlike API for posts and replies | E25: 5
C26: Add like buttons and counts to feed, post detail, and replies | E26: 5
C27: Update like counts instantly without reloading | E27: 3
C28: Review & check-in | E28: 2
C29: Document | E29: 2
A30: All | B30: As a team, we deliver a tested, demo-ready release. | D30: 3 | E30: =SUM(E31:E34) -> 26 | F30: =IF(COUNT(F31:F34)=0,"",SUM(F31:F34)) | G30: =IF(COUNT(G31:G34)=0,"",SUM(G31:G34)) | H30: =IF(COUNT(H31:H34)=0,"",SUM(H31:H34)) | I30: =IF(COUNT(I31:I34)=0,"",SUM(I31:I34))
C31: End-to-end testing of all main workflows | E31: 8
C32: Fix bugs found in testing | E32: 8
C33: Prepare final presentation and demo | E33: 6
C34: Final documentation and backlog update | E34: 4
A36: Total | D36: =D2+D9+D16+D23+D30 -> 26 | E36: =E2+E9+E16+E23+E30 -> 105 | F36: =IF(COUNT(F2,F9,F16,F23,F30)=0,"",N(F2)+N(F9)+N(F16)+N(F23)+N(F30)) | G36: =IF(COUNT(G2,G9,G16,G23,G30)=0,"",N(G2)+N(G9)+N(G16)+N(G23)+N(G30)) | H36: =IF(COUNT(H2,H9,H16,H23,H30)=0,"",N(H2)+N(H9)+N(H16)+N(H23)+N(H30)) | I36: =IF(COUNT(I2,I9,I16,I23,I30)=0,"",N(I2)+N(I9)+N(I16)+N(I23)+N(I30))
A38: Sprint 3: 11/1/2026 – 11/19/2026. Goal: AI summary twist, likes, testing, final demo.
A39: Fill in Hrs Left on task rows at each check-in; story and total rows add up automatically.
